<?xml version="1.0" encoding="utf-8"?><testsuites name="pytest tests"><testsuite name="pytest" errors="0" failures="6" skipped="2" tests="68" time="7.619" timestamp="2025-10-19T23:40:27.047378-05:00" hostname="debian"><testcase classname="test_jicofo" name="test_jicofo_container_running" time="0.013" /><testcase classname="test_jicofo" name="test_jicofo_xmpp_connection" time="0.004" /><testcase classname="test_jicofo" name="test_jicofo_logs_no_errors" time="0.003" /><testcase classname="test_jicofo" name="test_jicofo_process_running" time="0.079"><failure message="Failed: No se pudo verificar el proceso jicofo: Proceso jicofo no encontrado en el contenedor&#10;assert 'jicofo' in 'OCI runtime exec failed: exec failed: unable to start container process: exec: &quot;ps&quot;: executable file not found in $PATH: unknown\r\n'">test_jicofo.py:74: in test_jicofo_process_running
    assert 'jicofo' in output, "Proceso jicofo no encontrado en el contenedor"
E   AssertionError: Proceso jicofo no encontrado en el contenedor
E   assert 'jicofo' in 'OCI runtime exec failed: exec failed: unable to start container process: exec: "ps": executable file not found in $PATH: unknown\r\n'

During handling of the above exception, another exception occurred:
test_jicofo.py:77: in test_jicofo_process_running
    pytest.fail(f"No se pudo verificar el proceso jicofo: {e}")
E   Failed: No se pudo verificar el proceso jicofo: Proceso jicofo no encontrado en el contenedor
E   assert 'jicofo' in 'OCI runtime exec failed: exec failed: unable to start container process: exec: "ps": executable file not found in $PATH: unknown\r\n'</failure></testcase><testcase classname="test_jicofo" name="test_jicofo_configuration_files" time="0.099" /><testcase classname="test_jicofo" name="test_jicofo_authentication_setup" time="0.003" /><testcase classname="test_jicofo" name="test_jicofo_ready_for_conferences" time="0.003" /><testcase classname="test_jicofo" name="test_jicofo_network_connectivity" time="0.096" /><testcase classname="test_jvb" name="test_jvb_container_running" time="0.000" /><testcase classname="test_jvb" name="test_jvb_udp_port" time="0.059" /><testcase classname="test_jvb" name="test_jvb_logs_no_errors" time="0.002" /><testcase classname="test_jvb" name="test_jvb_process_running" time="0.067"><failure message="Failed: No se pudo verificar el proceso jvb: Proceso jvb no encontrado en el contenedor&#10;assert 'jvb' in &quot;error: garbage option\n\nUsage:\n ps [options]\n\n Try 'ps --help &lt;simple|list|output|threads|misc|all&gt;'\n  or 'ps --help &lt;s|l|o|t|m|a&gt;'\n for additional help text.\n\nFor more details see ps(1).\n&quot;">test_jvb.py:73: in test_jvb_process_running
    assert 'jvb' in output, "Proceso jvb no encontrado en el contenedor"
E   AssertionError: Proceso jvb no encontrado en el contenedor
E   assert 'jvb' in "error: garbage option\n\nUsage:\n ps [options]\n\n Try 'ps --help &lt;simple|list|output|threads|misc|all&gt;'\n  or 'ps --help &lt;s|l|o|t|m|a&gt;'\n for additional help text.\n\nFor more details see ps(1).\n"

During handling of the above exception, another exception occurred:
test_jvb.py:76: in test_jvb_process_running
    pytest.fail(f"No se pudo verificar el proceso jvb: {e}")
E   Failed: No se pudo verificar el proceso jvb: Proceso jvb no encontrado en el contenedor
E   assert 'jvb' in "error: garbage option\n\nUsage:\n ps [options]\n\n Try 'ps --help &lt;simple|list|output|threads|misc|all&gt;'\n  or 'ps --help &lt;s|l|o|t|m|a&gt;'\n for additional help text.\n\nFor more details see ps(1).\n"</failure></testcase><testcase classname="test_jvb" name="test_jvb_configuration_files" time="0.130" /><testcase classname="test_jvb" name="test_jvb_network_interfaces" time="0.070" /><testcase classname="test_jvb" name="test_jvb_ready_for_conferences" time="0.003" /><testcase classname="test_jvb" name="test_jvb_rtp_port_binding" time="0.049" /><testcase classname="test_jvb" name="test_jvb_memory_usage" time="1.006" /><testcase classname="test_jvb" name="test_jvb_network_connectivity" time="0.156" /><testcase classname="test_prosody" name="test_prosody_container_running" time="0.000" /><testcase classname="test_prosody" name="test_prosody_ports_open" time="0.001" /><testcase classname="test_prosody" name="test_prosody_logs_no_errors" time="0.003" /><testcase classname="test_prosody" name="test_prosody_xmpp_connection" time="0.078"><failure message="Failed: No se pudo verificar el proceso prosody: Proceso prosody no encontrado en el contenedor&#10;assert 'prosody' in &quot;error: garbage option\n\nUsage:\n ps [options]\n\n Try 'ps --help &lt;simple|list|output|threads|misc|all&gt;'\n  or 'ps --help &lt;s|l|o|t|m|a&gt;'\n for additional help text.\n\nFor more details see ps(1).\n&quot;">test_prosody.py:58: in test_prosody_xmpp_connection
    assert 'prosody' in output, "Proceso prosody no encontrado en el contenedor"
E   AssertionError: Proceso prosody no encontrado en el contenedor
E   assert 'prosody' in "error: garbage option\n\nUsage:\n ps [options]\n\n Try 'ps --help &lt;simple|list|output|threads|misc|all&gt;'\n  or 'ps --help &lt;s|l|o|t|m|a&gt;'\n for additional help text.\n\nFor more details see ps(1).\n"

During handling of the above exception, another exception occurred:
test_prosody.py:61: in test_prosody_xmpp_connection
    pytest.fail(f"No se pudo verificar el proceso prosody: {e}")
E   Failed: No se pudo verificar el proceso prosody: Proceso prosody no encontrado en el contenedor
E   assert 'prosody' in "error: garbage option\n\nUsage:\n ps [options]\n\n Try 'ps --help &lt;simple|list|output|threads|misc|all&gt;'\n  or 'ps --help &lt;s|l|o|t|m|a&gt;'\n for additional help text.\n\nFor more details see ps(1).\n"</failure></testcase><testcase classname="test_prosody" name="test_prosody_configuration_files" time="0.049"><failure message="Failed: Error verificando archivo /etc/prosody/prosody.cfg.lua: Archivo de configuraci贸n no encontrado: /etc/prosody/prosody.cfg.lua&#10;assert 1 == 0&#10; +  where 1 = ExecResult(exit_code=1, output=b'').exit_code">test_prosody.py:77: in test_prosody_configuration_files
    assert result.exit_code == 0, f"Archivo de configuraci贸n no encontrado: {config_file}"
E   AssertionError: Archivo de configuraci贸n no encontrado: /etc/prosody/prosody.cfg.lua
E   assert 1 == 0
E    +  where 1 = ExecResult(exit_code=1, output=b'').exit_code

During handling of the above exception, another exception occurred:
test_prosody.py:80: in test_prosody_configuration_files
    pytest.fail(f"Error verificando archivo {config_file}: {e}")
E   Failed: Error verificando archivo /etc/prosody/prosody.cfg.lua: Archivo de configuraci贸n no encontrado: /etc/prosody/prosody.cfg.lua
E   assert 1 == 0
E    +  where 1 = ExecResult(exit_code=1, output=b'').exit_code</failure></testcase><testcase classname="test_prosody" name="test_prosody_database_connection" time="0.003" /><testcase classname="test_prosody" name="test_prosody_websocket_endpoint" time="0.002" /><testcase classname="test_web" name="test_web_container_running" time="0.000" /><testcase classname="test_web" name="test_web_http_accessible" time="0.002" /><testcase classname="test_web" name="test_web_http_200" time="0.002" /><testcase classname="test_web" name="test_web_content_type" time="0.002" /><testcase classname="test_web" name="test_web_jitsi_meet_page" time="0.002" /><testcase classname="test_web" name="test_web_config_js_accessible" time="0.002" /><testcase classname="test_web" name="test_web_static_assets" time="0.090" /><testcase classname="test_web" name="test_web_websocket_endpoint" time="0.003" /><testcase classname="test_web" name="test_web_logs_no_errors" time="0.003" /><testcase classname="test_web" name="test_web_nginx_process" time="0.065"><failure message="Failed: No se pudo verificar el proceso nginx: Proceso nginx no encontrado en el contenedor&#10;assert 'nginx' in 'OCI runtime exec failed: exec failed: unable to start container process: exec: &quot;ps&quot;: executable file not found in $PATH: unknown\r\n'">test_web.py:150: in test_web_nginx_process
    assert 'nginx' in output, "Proceso nginx no encontrado en el contenedor"
E   AssertionError: Proceso nginx no encontrado en el contenedor
E   assert 'nginx' in 'OCI runtime exec failed: exec failed: unable to start container process: exec: "ps": executable file not found in $PATH: unknown\r\n'

During handling of the above exception, another exception occurred:
test_web.py:153: in test_web_nginx_process
    pytest.fail(f"No se pudo verificar el proceso nginx: {e}")
E   Failed: No se pudo verificar el proceso nginx: Proceso nginx no encontrado en el contenedor
E   assert 'nginx' in 'OCI runtime exec failed: exec failed: unable to start container process: exec: "ps": executable file not found in $PATH: unknown\r\n'</failure></testcase><testcase classname="test_web" name="test_web_nginx_configuration" time="0.080" /><testcase classname="test_web" name="test_web_room_creation" time="0.002" /><testcase classname="test_web" name="test_web_https_redirect" time="0.002" /><testcase classname="test_websocket" name="test_websocket_port_5280" time="0.000" /><testcase classname="test_websocket" name="test_websocket_port_5222" time="0.000" /><testcase classname="test_websocket" name="test_websocket_no_errors_in_logs" time="0.002" /><testcase classname="test_websocket" name="test_websocket_endpoint_accessible" time="0.001" /><testcase classname="test_websocket" name="test_websocket_strophe_connection_simulation" time="0.000" /><testcase classname="test_websocket" name="test_websocket_prosody_listening" time="0.071" /><testcase classname="test_websocket" name="test_websocket_xmpp_port_listening" time="0.053" /><testcase classname="test_websocket" name="test_websocket_cross_origin_headers" time="0.002" /><testcase classname="test_websocket" name="test_websocket_ssl_tls_support" time="5.012" /><testcase classname="test_websocket" name="test_websocket_connection_timeout" time="0.000" /><testcase classname="test_websocket" name="test_websocket_multiple_connections" time="0.001" /><testcase classname="test_websocket" name="test_websocket_prosody_modules" time="0.076" /><testcase classname="test_websocket_error_specific" name="test_specific_error_url_detection" time="0.000" /><testcase classname="test_websocket_error_specific" name="test_url_construction_simulation" time="0.000" /><testcase classname="test_websocket_error_specific" name="test_error_root_cause_analysis" time="0.000" /><testcase classname="test_websocket_error_specific" name="test_error_detection_patterns" time="0.000" /><testcase classname="test_websocket_error_specific" name="test_error_fix_validation" time="0.000" /><testcase classname="test_websocket_error_specific" name="test_error_specific_room_parameter" time="0.000"><failure message="AssertionError: Error no est谩 en la parte del protocolo&#10;assert 'http//' in 'http'&#10; +  where 'http' = ParseResult(scheme='wss', netloc='http', path='//localhost:8080/xmpp-websocket', params='', query='room=recentconcessionscrysure', fragment='').netloc">test_websocket_error_specific.py:134: in test_error_specific_room_parameter
    assert 'http//' in parsed.netloc, "Error no est谩 en la parte del protocolo"
E   AssertionError: Error no est谩 en la parte del protocolo
E   assert 'http//' in 'http'
E    +  where 'http' = ParseResult(scheme='wss', netloc='http', path='//localhost:8080/xmpp-websocket', params='', query='room=recentconcessionscrysure', fragment='').netloc</failure></testcase><testcase classname="test_websocket_error_specific" name="test_error_environment_variables_impact" time="0.000" /><testcase classname="test_websocket_error_specific" name="test_error_log_analysis" time="0.001" /><testcase classname="test_websocket_error_specific" name="test_error_solution_verification" time="0.000" /><testcase classname="test_websocket_url" name="test_public_url_format" time="0.000" /><testcase classname="test_websocket_url" name="test_websocket_url_validation" time="0.000"><skipped type="pytest.skip" message="Helper de validaci贸n no disponible">/home/dopel/projects/jitsi-django/jitsi/tests/test_websocket_url.py:63: Helper de validaci贸n no disponible</skipped></testcase><testcase classname="test_websocket_url" name="test_detect_malformed_url_pattern" time="0.000" /><testcase classname="test_websocket_url" name="test_url_construction_simulation" time="0.000" /><testcase classname="test_websocket_url" name="test_websocket_url_parsing" time="0.000" /><testcase classname="test_websocket_url" name="test_malformed_url_detection_patterns" time="0.000" /><testcase classname="test_websocket_url" name="test_websocket_url_validation_helper_integration" time="0.000"><skipped type="pytest.skip" message="Helper de validaci贸n no disponible">/home/dopel/projects/jitsi-django/jitsi/tests/test_websocket_url.py:205: Helper de validaci贸n no disponible</skipped></testcase><testcase classname="test_websocket_url" name="test_environment_variables_consistency" time="0.000" /><testcase classname="test_websocket_url" name="test_websocket_url_construction_edge_cases" time="0.000" /></testsuite></testsuites>